<?xml version="1.0"?>
<robot name="spatial_3R_robot">

<material name="blue">
  <color rgba="0 0 0.4 1"/>
</material>

<material name="light_blue">
  <color rgba="0.0 0.0 0.9 1"/>
</material>

<material name="red">
  <color rgba="0.8 0 0 1"/>
</material>

<material name="green">
  <color rgba="0.1 0.8 0.1 1"/>
</material>

<material name="black">
  <color rgba="0.0 0.0 0.0 1"/>
</material>

<link name="world"/>

<joint name="rotation0" type="revolute">
  <parent link="world"/>
  <child link="base_link"/>
  <origin xyz="0 0.0 0" rpy="0 0 0"/>
  <axis xyz="0 0 1"/>
  <limit effort="100" velocity="10"/>

</joint>

<link name="base_link">
  <collision>
    <origin xyz="0 0 0.2" rpy="0 0 0"/>
    <geometry>
      <cylinder length="1.0" radius="0.1"/>
    </geometry>
  </collision>

  <visual>
    <origin xyz="0 0 0.5" rpy="0 0 0"/>
    <geometry>
      <cylinder length="1.0" radius="0.1"/>
    </geometry>
    <material name="red" />
  </visual>

  <inertial>
    <origin xyz="0 0 0.5" rpy="0 0 0"/>
    <mass value="1"/>
    <inertia
      ixx="1.0" ixy="0.0" ixz="0.0"
      iyy="1.0" iyz="0.0"
      izz="1.0"/>
  </inertial>
</link>

<joint name="rotation1" type="revolute">
  <parent link="base_link"/>
  <child link="arm1"/>
  <origin xyz="0 0 1.0" rpy="0 1.57075 0"/>
  <axis xyz="0 0 1"/>
   <limit effort="100" velocity="10"/>
</joint>

<link name="arm1">
  <collision>
    <origin xyz="0 -0.5 0.0" rpy="0 0 0"/>
    <geometry>
      <box size="0.1 1.1 0.1"/>
    </geometry>
  </collision>

  <visual>
    <origin xyz="0 -0.5 0.0" rpy="0 0 0"/>
    <geometry>
      <box size="0.1 1.1 0.1"/>
    </geometry>
    <material name="blue" />
  </visual>

  <inertial>
    <origin xyz="0 0 0.0" rpy="0 0 0"/>
    <mass value="1"/>
    <inertia
      ixx="0.001" ixy="0.0" ixz="0.0"
      iyy="0.001" iyz="0.0"
      izz="0.001"/>
  </inertial>
</link>

<joint name="rotation2" type="revolute">
  <parent link="arm1"/>
  <child link="arm2"/>
  <origin xyz="0 -1 0.0" rpy="0 0 0"/>
  <axis xyz="0 0 1"/>
  <limit effort="1000" velocity="1000"/>
</joint>

<link name="arm2">
  <collision>
    <origin xyz="0 -0.4 0.0" rpy="0 0 0"/>
    <geometry>
      <box size="0.1 0.9 0.1"/>
    </geometry>
  </collision>

  <visual>
    <origin xyz="0 -0.4 0.0" rpy="0 0 0"/>
    <geometry>
      <box size="0.1 0.9 0.1"/>
    </geometry>
    <material name="light_blue" />
  </visual>

  <inertial>
    <origin xyz="0 0 0.0" rpy="0 0 0"/>
    <mass value="1"/>
    <inertia
      ixx="0.001" ixy="0.0" ixz="0.0"
      iyy="0.001" iyz="0.0"
      izz="0.001"/>
  </inertial>
</link>

<joint name="prismatic_joint" type="prismatic">
  <parent link="arm2"/>
  <child link="arm3"/>
  <origin xyz="0 0.0 0.0" rpy="0 0 0"/>
  <axis xyz="1 0 0"/>
  <limit lower="0.0" upper="1.0" effort="1000" velocity="0.5"/>
</joint>

<link name="arm3">
  <collision>
    <origin xyz="-0.5 -0.9 0" rpy="0 0 0"/>
    <geometry>
      <box size="1.0 0.1 0.1"/>
    </geometry>
  </collision>
  <visual>
    <origin xyz="-0.5 -0.9 0" rpy="0 0 0"/>
    <geometry>
      <box size="1.0 0.1 0.1"/>
    </geometry>
    <material name="black" />
  </visual>
  <inertial>
    <origin xyz="0 0 0.0" rpy="0 0 0"/>
    <mass value="1"/>
    <inertia
      ixx="0.001" ixy="0.0" ixz="0.0"
      iyy="0.001" iyz="0.0"
      izz="0.001"/>
  </inertial>
</link>

<joint name="fixed1" type="fixed">
  <parent link="arm3"/>
  <child link="tool0"/>
  <origin xyz="0 -0.9 0.0" rpy="0 0 0"/>
  <axis xyz="0 0 1"/>
</joint>

<link name="tool0">
  <collision>
    <origin xyz="0.5 -0.9 0.0" rpy="0 0 0"/>
    <geometry>
      <box size="0.1 0.1 0.1"/>
    </geometry>
  </collision>

  <visual>
    <origin xyz="0 0.0 0.0" rpy="0 0 0"/>
    <geometry>
      <box size="0.1 0.1 0.1"/>
    </geometry>
    <material name="green" />
  </visual>

  <inertial>
    <origin xyz="0.0 0.0 0.0" rpy="0 0 0"/>
    <mass value="1"/>
    <inertia
      ixx="0.001" ixy="0.0" ixz="0.0"
      iyy="0.001" iyz="0.0"
      izz="0.001"/>
  </inertial>
</link>

</robot>