<?xml version="1.0" ?>
<!-- =================================================================================== -->
<!-- |    This document was autogenerated by xacro from single_rrbot.urdf.xacro        | -->
<!-- |    EDITING THIS FILE BY HAND IS NOT RECOMMENDED                                 | -->
<!-- =================================================================================== -->
<robot name="single_rrbot" xmlns:xacro="http://www.ros.org/wiki/xacro">
  <!-- Import your models -->
  <material name="RRBOT/black">
    <color rgba="0.0 0.0 0.0 1.0"/>
  </material>
  <material name="RRBOT/blue">
    <color rgba="0.0 0.0 0.8 1.0"/>
  </material>
  <material name="RRBOT/green">
    <color rgba="0.0 0.8 0.0 1.0"/>
  </material>
  <material name="RRBOT/grey">
    <color rgba="0.2 0.2 0.2 1.0"/>
  </material>
  <material name="RRBOT/orange">
    <color rgba="1.0 0.423529411765 0.0392156862745 1.0"/>
  </material>
  <material name="RRBOT/brown">
    <color rgba="0.870588235294 0.811764705882 0.764705882353 1.0"/>
  </material>
  <material name="RRBOT/red">
    <color rgba="0.8 0.0 0.0 1.0"/>
  </material>
  <material name="RRBOT/white">
    <color rgba="1.0 1.0 1.0 1.0"/>
  </material>
  <!-- Build your comprehensive robot -->
  <link name="world"/>
  <joint name="single_rrbot_fixed" type="fixed">
    <origin rpy="0 0 0" xyz="0 0 0"/>
    <parent link="world"/>
    <child link="single_rrbot_link1"/>
  </joint>

  <link name="single_rrbot_link1">
  </link>
  <joint name="single_rrbot_joint1" type="continuous">
    <parent link="single_rrbot_link1"/>
    <child link="single_rrbot_link2"/>
    <origin rpy="0 0 0" xyz="0 0 1"/>
    <axis xyz="0 0 1"/>
    <dynamics damping="0.7"/>
    <limit lower="0" upper="1.57079633" effort="30.0" velocity="1.0"/>
  </joint>

  <link name="single_rrbot_link2">
  </link>
  <joint name="single_rrbot_joint2" type="continuous">
    <parent link="single_rrbot_link2"/>
    <child link="single_rrbot_link3"/>
    <origin rpy="0 0 0" xyz="1 0 0"/>
    <axis xyz="0 0 1"/>
    <dynamics damping="0.7"/>
    <limit lower="-1.57079633" upper="0" effort="30.0" velocity="1.0"/>
  </joint>

  <link name="single_rrbot_link3">
  </link>
  <joint name="single_rrbot_joint3" type="continuous">
    <parent link="single_rrbot_link3"/>
    <child link="single_rrbot_link4"/>
    <origin rpy="0 0 0" xyz="1 0 0"/>
    <axis xyz="0 0 1"/>
    <dynamics damping="0.7"/>
    <limit lower="0" upper="3.14159265" effort="30.0" velocity="1.0"/>
  </joint>

  <link name="single_rrbot_link4">
  </link>
    <joint name="single_rrbot_joint4" type="prismatic">
    <parent link="single_rrbot_link4"/>
    <child link="single_rrbot_link5"/>
    <origin rpy="0 0 0" xyz="0 0 -0.5"/>
    <axis xyz="0 0 1"/>
    <dynamics damping="0.7"/>
    <limit lower="-1" upper="0" effort="30.0" velocity="1.0"/>
  </joint>

  <link name="single_rrbot_link5">
    </link>
  <transmission name="single_rrbot_tran1">
    <type>transmission_interface/SimpleTransmission</type>
    <joint name="single_rrbot_joint1">
      <hardwareInterface>PositionJointInterface</hardwareInterface>
    </joint>
    <actuator name="single_rrbot_motor1">
      <mechanicalReduction>1</mechanicalReduction>
    </actuator>
  </transmission>
  <transmission name="single_rrbot_tran2">
    <type>transmission_interface/SimpleTransmission</type>
    <joint name="single_rrbot_joint2">
      <hardwareInterface>PositionJointInterface</hardwareInterface>
    </joint>
    <actuator name="single_rrbot_motor2">
      <mechanicalReduction>1</mechanicalReduction>
    </actuator>
  </transmission>
  <transmission name="single_rrbot_tran3">
    <type>transmission_interface/SimpleTransmission</type>
    <joint name="single_rrbot_joint3">
      <hardwareInterface>PositionJointInterface</hardwareInterface>
    </joint>
    <actuator name="single_rrbot_motor3">
      <mechanicalReduction>1</mechanicalReduction>
    </actuator>
  </transmission>
  <transmission name="single_rrbot_tran4">
    <type>transmission_interface/SimpleTransmission</type>
    <joint name="single_rrbot_joint4">
      <hardwareInterface>PositionJointInterface</hardwareInterface>
    </joint>
    <actuator name="single_rrbot_motor4">
      <mechanicalReduction>1</mechanicalReduction>
    </actuator>
  </transmission>
</robot>
